<mujocoinclude model="MyoArm_v0.2">
    <!-- <light pos="0 0 1.5" dir="0 0 -1" directional="true"/>
    <geom type="plane" size="3 3 .01" material="grid" pos = "0 0 -1"/> -->
    <!-- <geom type="sphere" size="0.05" rgba="1 0 0 1" pos="0 0 0"/> -->
    <body name="static" pos = "0 0 0.89 " quat="0 0 0.7071 0.7071">
        <!-- <joint type="free"/> -->
        <geom mesh="frame" material="metal" conaffinity="0" contype="0"/>
        <geom mesh="armrest1" material="orange"/>
        <geom mesh="armrest2" material="orange"/>
        <geom mesh="backrest" material="dark_blue"/>
        <geom mesh="footplate1" material="grey"/>
        <geom mesh="footplate2" material="grey"/>
        <geom mesh="push_handle1" material="cyan"/>
        <geom mesh="push_handle2" material="cyan"/>
        <geom mesh="seat" material="dark_blue"/>
        <geom mesh="side_panel1" material="metal"/>
        <geom mesh="side_panel2" material="metal"/>
        
        <body name = "left_rear_wheel" pos="-0.0635 -0.5842 -0.1524">
            <joint name= "left_rear" axis="-1 0 0" damping=".03"/>
            <geom mesh= "rear_wheel1" pos="0.0635 0.5842 0.1524" material="dark_grey" conaffinity="0" contype="0"/>
            <geom name = "left_rear_coll" type="cylinder" size="0.3048" fromto="-0.0127 0 0 0.0127 0 0" rgba="1 0 0 0"/>
            <!-- <geom name = "left_handrail_coll" type="cylinder" pos = "-0.038 0 0" size="0.2762 0.0082" euler="0 1.5708 0" rgba="0 0 1 0"/> -->
            <body name = "left_handrail" pos="0 0 0">
                <geom mesh="handrail_coll1" pos="-0.0371 0 0" rgba="0 0 1 0"/>
                <geom mesh="handrail_coll2" pos="-0.0371 0 0" rgba="0 0 1 0"/>
                <geom mesh="handrail_coll3" pos="-0.0371 0 0" rgba="0 0 1 0"/>
                <geom mesh="handrail_coll4" pos="-0.0371 0 0" rgba="0 0 1 0"/>
                <geom mesh="handrail_coll5" pos="-0.0371 0 0" rgba="0 0 1 0"/>
                <geom mesh="handrail_coll6" pos="-0.0371 0 0" rgba="0 0 1 0"/>
                <geom mesh="handrail_coll7" pos="-0.0371 0 0" rgba="0 0 1 0"/>
                <geom mesh="handrail_coll8" pos="-0.0371 0 0" rgba="0 0 1 0"/>
                <geom mesh="handrail_coll9" pos="-0.0371 0 0" rgba="0 0 1 0"/>
                <geom mesh="handrail_coll10" pos="-0.0371 0 0" rgba="0 0 1 0"/>
                <geom mesh="handrail_coll11" pos="-0.0371 0 0" rgba="0 0 1 0"/>
                <geom mesh="handrail_coll12" pos="-0.0371 0 0" rgba="0 0 1 0"/>
                <geom mesh="handrail_coll13" pos="-0.0371 0 0" rgba="0 0 1 0"/>
                <geom mesh="handrail_coll14" pos="-0.0371 0 0" rgba="0 0 1 0"/>
                <geom mesh="handrail_coll15" pos="-0.0371 0 0" rgba="0 0 1 0"/>
                <geom mesh="handrail_coll16" pos="-0.0371 0 0" rgba="0 0 1 0"/>
            </body>  
            <!-- <site name="wheel" size="0.005"/>  -->
            <site name="wheelchair_grip_left" pos="-0.0371 0.27 0.05" size="0.005" rgba="0 1 0 0.5"/>
        </body>
        <site name="hand_start_right" pos="0.5324 -0.3142 -0.1024" size="0.008" rgba="1 0 0 1"/>
        <site name="hand_TARGET_right" pos="0.5324 -0.4542 -0.395" size="0.008" rgba="0 0 1 1"/>

        <site name="hand_start_left" pos="-0.101 -0.3142 -0.1024" size="0.008" rgba="1 0 0 1"/>
        <site name="hand_TARGET_left" pos="-0.101 -0.4542 -0.395" size="0.008" rgba="0 0 1 1"/>

        <body name = "right_rear_wheel" pos="0.4953 -0.5842 -0.1524">
            <joint name= "right_rear" axis="-1 0 0" damping=".03"/>
            <geom mesh= "rear_wheel2" pos="-0.4953 0.5842 0.1524" material="dark_grey" conaffinity="0" contype="0"/>
            <geom name = "right_rear_coll" type="cylinder" size="0.3048" fromto="-0.0127 0 0 0.0127 0 0" rgba="1 0 0 0"/>
            <!-- <geom name = "right_handrail_coll" type="cylinder" pos = "0.038 0 0" size="0.2762 0.0082" euler="0 1.5708 0" rgba="0 0 1 0"/> -->
            <body name = "right_handrail" pos="0.0371 0 0">
                <geom mesh="handrail_coll1" pos="0 0 0" rgba="0 0 1 1"/>
                <geom mesh="handrail_coll2" pos="0 0 0" rgba="0 0 1 0"/>
                <geom mesh="handrail_coll3" pos="0 0 0" rgba="0 0 1 0"/>
                <geom mesh="handrail_coll4" pos="0 0 0" rgba="0 0 1 0"/>
                <geom mesh="handrail_coll5" pos="0 0 0" rgba="0 0 1 0"/>
                <geom mesh="handrail_coll6" pos="0. 0 0" rgba="0 0 1 0"/>
                <geom mesh="handrail_coll7" pos="0 0 0" rgba="0 0 1 0"/>
                <geom mesh="handrail_coll8" pos="0 0 0" rgba="0 0 1 0"/>
                <geom mesh="handrail_coll9" pos="0 0 0" rgba="0 0 1 0"/>
                <geom mesh="handrail_coll10" pos="0. 0 0" rgba="0 0 1 0"/>
                <geom mesh="handrail_coll11" pos="0 0 0" rgba="0 0 1 0"/>
                <geom mesh="handrail_coll12" pos="0. 0 0" rgba="0 0 1 0"/>
                <geom mesh="handrail_coll13" pos="0 0 0" rgba="0 0 1 0"/>
                <geom mesh="handrail_coll14" pos="0 0 0" rgba="0 0 1 0"/>
                <geom mesh="handrail_coll15" pos="0 0 0" rgba="0 0 1 0"/>
                <geom mesh="handrail_coll16" pos="0 0 0" rgba="0 0 1 0"/>
            </body>    
            
            <site name="wheelchair_grip_right" pos="0.0371 0.27 0.05" size="0.005" rgba="0 1 0 1"/>
            <site name="rail_bottom_right" pos="0.0371 0.25 0.05" size="0.005" rgba="0 0 1 1"/>

            <site name="rail_bottom_left" pos="-0.0371 0.25 0.05" size="0.005" rgba="0 0 1 1"/>
            
            <!-- <geom type = "sphere" pos="0.0371 0.27 0.05" size = "0.008" rgba="1 0 0 1"/> -->
        </body>
        
        <body name = "left_fork" pos="0 -0.78105 -0.607055">
            <joint name= "left_fork" axis="0 -1 0" damping=".03" limited="true" range="-60 60"/>
            <geom mesh= "caster_fork1" pos="0 0.78105 0.607055" material="metal"/>
            <geom mesh= "pin1" pos="0 0.78105 0.607055" material="metal"/>
                
            <body name = "left_caster_wheel" pos="0 0 -0.049375">
                <joint name= "left_caster" axis="-1 0 0" damping=".03"/>
                <geom mesh= "caster_wheel1" pos="0 0.78105 0.65643" material="dark_grey"/>
            </body>
            
        </body>
        <body name = "right_fork" pos="0.4318 -0.78105 -0.60563">
            <joint name= "right_fork" axis="0 -1 0" damping=".03" limited="true" range="-60 60"/>
            <geom mesh= "caster_fork2" pos="-0.4318 0.78105 0.60563" material="metal"/>
            <geom mesh= "pin2" pos="-0.4318 0.78105 0.60563" material="metal"/>
            
            <body name = "right_caster_wheel" pos="0 0 -0.0508">
                <joint name= "right_caster" axis="-1 0 0" damping=".03"/>
                <geom mesh= "caster_wheel2" pos="-0.4318 0.78105 0.65643" material="dark_grey"/>
            </body> 
            
        </body>
    </body>
</mujocoinclude>