<mujocoinclude>
<!-- =================================================
    Copyright 2024 Vikash Kumar
    Model   :: UT Exo
    Author  :: Vikash Kumar (vikashplus@gmail.com)
    source  :: https://github.com/vikashplus
    License :: contact vikashplus@gmail.com
====================================================== -->

	<!-- FOR MUJOCO:
    fullinertia="Ixx Iyy Izz Ixy Ixz Iyz"   
     -->


    <!-- PART3 - shoe connection part -->
	<body name="part3_sx" pos="0 0 0.05" euler="0 0 1.57" childclass="ut_exo_sx">
		<inertial pos="-0.194085 0.000792 0.050867 " mass="0.4455" fullinertia = "0.5817e-03    1.0000e-03    0.8725e-03   -0.0221e-03   -0.0094e-03   -0.1075e-03"/>
        <geom type="mesh" mesh="part3_sx" class="ut_exo_sx" pos="-0.12 0 0.0375" euler="1.57 0 0" rgba="0.65 0.6 0.6 1"/>
		<geom type="box" size=".075 .015 .05" pos="-0.192 0 0.05" class="ut_exo_coll_sx"/>
		<site name="part3_to_part1_on_parent_sx"  pos="-.12 0 0.04" rgba="0 1 0 1"/>
		<site name="Far_vedere_attacco" pos="-.24 .05 .1" size="1" rgba="1 1 1 0"/>
		<!-- <geom name="cyl_contact1_sx" type="cylinder" size="0.005 0.041" pos="-0.245 0.052 0.005" euler="1.57 0 1.57"  rgba="0.4 0.4 0.6 1"  class ="ut_exo_sx"/> -->
		<!-- <geom name="cyl_contact2_sx" type="cylinder" size="0.005 0.041" pos="-0.17 0.052 0.005" euler="1.57 0 1.57" rgba="0.4 0.4 0.6 1" class ="ut_exo_sx"/> -->
		<!-- <freejoint name="exo_free"/> -->

		<!-- PART2 - upper part -->
		<body name="part2_sx" pos="-.005 0 0.0975" euler="0 0 0">
			<inertial pos="-0.1922 -0.002767 0.095074" mass="0.318" fullinertia = "0.8018e-03    0.8480e-03    0.2663e-03   0.0728e-03    0.0101e-03    0.0116e-03"/>
			<geom type="mesh" mesh="part2_sx" class="ut_exo_sx" pos="-0.195 0.0005 0" euler="1.57 0 0"/>
			<geom type="box" size=".04 .01 .1" pos="-.215 0 0.1" class="ut_exo_coll_sx"/>
			<joint name="joint2_sx" pos="-0.195 0.0005 0" axis="0 -1 0" range="-.86 .52" damping = "0.2"/>  
			<site name="part2_attach_sx" pos="-.164 0 0.185" rgba="0 1 1 1"/>
			<site name="part2_to_part3_encoder_sx" pos="-0.195 0.0005 0" rgba="0 1 0 1"/>
			<!-- <geom name="cyl_contact3_sx" type="cylinder" size="0.005 0.042" pos="-0.241 0.052 0.101" euler="1.57 0 1.57" rgba="0.4 0.4 0.6 1" class ="ut_exo_coll_sx"/> -->
		</body>

		<!-- PART1- load cell -->
		<body name="part1_sx" pos="-.09 0 0.0375" euler="0 0 0">
			<inertial pos="-0.035204 -0.000454 0.047435 " mass="0.1832" fullinertia = "0.2253e-03    0.2340e-03    0.0222e-03         0   0.0309e-03         0"/>
			<geom type="mesh" mesh="part1_sx" class="ut_exo_sx" pos="-.03 0 0" euler="1.57 0 -3.04"/>
			<joint name="joint1_sx" pos="-.03 0 0" axis="0 -1 0" range="-0.7 0.55" damping = "0.1"/>
			<site name="part1_attach_sx" pos="-0.034 0 0.04"  rgba="1 0 0 1"/>
			<site name="part3_attach_sx" pos="-0.04 0 0.0748"/>
			<site name="part3_to_part1_on_part1_sx" pos="-0.03 0 0.0" rgba="0 0 0 1" />
		</body>

	</body>

</mujocoinclude>