<mujocoinclude>
<!-- =================================================
    Copyright 2024 Vikash Kumar
    Model   :: UT Exo
    Author  :: Vikash Kumar (vikashplus@gmail.com)
    source  :: https://github.com/vikashplus
    License :: contact vikashplus@gmail.com
====================================================== -->

<!-- FOR MUJOCO:
    fullinertia="Ixx Iyy Izz Ixy Ixz Iyz"   
     -->


    <!-- PART3 - shoe connection part -->
	<body name="part3_dx" pos="0 0 0.05" euler="0 0 1.57" childclass="ut_exo_dx">
		<inertial pos="-0.044085 0.000792 0.050867 " mass="0.4455" fullinertia = "0.5817e-03    1.0000e-03    0.8725e-03   -0.0221e-03   -0.0094e-03   -0.1075e-03"/>
		<!-- <inertial pos="-0.044085 0.000792 0.050867 " mass="0.4455" diaginertia = "0.5817e-03    1.0000e-03    0.8725e-03"/>  -->
		<geom type="mesh" mesh="part3_dx" class="ut_exo_dx" pos="-.12 0 0.0375" euler="1.57 0 0" rgba="0.65 0.6 0.6 1"/>
		<geom type="box" size=".075 .015 .05" pos="-0.05 0 0.05" class="ut_exo_coll_dx"/>
		<site name="part3_to_part1_on_parent_dx"  pos="-.12 0 0.04" rgba="0 1 0 1"/>
		<site name="constraint_tibia"  pos=".012 .06 .2" size="0.015" rgba="0 1 0 1"/>
		<!-- <geom name="cyl_contact1_dx" type="cylinder" size="0.005 0.044" pos="-0.07 0.055 0.005" euler="1.57 0 1.57"  rgba="0.4 0.4 0.6 1"  class ="ut_exo_dx"/> -->
		<!-- <geom name="cyl_contact2_dx" type="cylinder" size="0.005 0.044" pos="0.005 0.055 0.005" euler="1.57 0 1.57" rgba="0.4 0.4 0.6 1" class ="ut_exo_dx"/> -->

		<!-- <freejoint name="exo_free"/> -->

		<!-- PART2 - upper part -->
		<body name="part2_dx" pos="-.005 0 0.0975" euler="0 0 0">
			<inertial pos="-0.03022 -0.002767 0.095074" mass="0.318" fullinertia = "0.8018e-03    0.8480e-03    0.2663e-03   -0.0728e-03    0.0101e-03    0.0116e-03"/>
			<geom type="mesh" mesh="part2_dx" class="ut_exo_dx" pos="-0.035 0 0" euler="1.57 0 0"/>
			<geom type="box" size=".04 .01 .1" pos="-.015 0 0.1" class="ut_exo_coll_dx"/>
			<joint name="joint2_dx" pos="-0.035 0 0" axis="0 1 0" range="-.86 .52" damping = "0.1"/> 
			<site name="part2_attach_dx" pos="-.067 0 0.185"  rgba="0 1 1 1"/>
			<site name="part2_to_part3_encoder_dx" pos="-.035 0 0" rgba="0 1 0 1"/>
			<site name="constraint_talus"  pos=".01 .07 -0.085" size="0.015" rgba="1 0 0 1"/>
			<site name="constraint_calcagno"  pos="-0.06 .07 -0.085" size="0.015" rgba="1 1 0 1"/>
			<!-- <geom name="cyl_contact3_dx" type="cylinder" size="0.0046 0.042" pos="0.0106 0.05 0.101" euler="1.57 0 1.57" rgba="0.4 0.4 0.6 1" class ="ut_exo_coll_dx"/> -->

		</body>

		<!-- PART1- load cell -->
		<body name="part1_dx" pos="-.09 0 0.0375" euler="0 0 0">
			<inertial pos="-0.026204 -0.000454 0.047435 " mass="0.1832" fullinertia = "0.2253e-03    0.2340e-03    0.0222e-03         0   -0.0409e-03         0"/>
			<geom type="mesh" mesh="part1_dx" class="ut_exo_dx" pos="-.03 0 0" euler="1.57 0 3.04"/>
			<joint name="joint1_dx" pos="-.03 0 0" axis="0 1 0" range="-.7 0.55" damping = "0.1"/>
			<site name="part1_attach_dx" pos="-0.026 0 0.04" rgba="1 0 0 1"/>
			<site name="part3_attach_dx" pos="-0.022 0 0.0748"/>
			<site name="part3_to_part1_on_part1_dx" pos="-0.03 0 0.0" size="0.01" rgba="0 0 0 1" />
		</body>

	</body>

</mujocoinclude>
